<?xml version="1.0"?>
<robot name="rae"
  xmlns:xacro="http://ros.org/wiki/xacro">
  <xacro:arg name="sim_mode" default="false" />

  <xacro:include filename="inertial_moment_calc.xacro"/>
  <xacro:include filename="rae_ros2_control.urdf.xacro"/>
  <xacro:property name="deg_to_rad" value="0.01745329251994329577" />

  <link name="base_footprint"/>
  <joint name="dummy" type="fixed">
    <parent link="base_footprint"/>
    <child link="base_link"/>
    <origin rpy="0 0.0 0" xyz="0 0.0 0.0" />
  </joint>
  <link name="base_link">
    <xacro:body mass="0.00001" d="0.0000010" h="0.000003" w="0.00003">
      <origin xyz="0.0 0.0 0.0" rpy="0.0 0.0 0.0"/>
    </xacro:body>
  </link>
  <xacro:if value="$(arg sim_mode)">
    <gazebo reference="rae_imu_frame">
      <sensor name="rae_imu_sensor" type="imu">
        <always_on>1</always_on>
        <update_rate>10.0</update_rate>
        <visualize>true</visualize>
        <topic>rae/imu/data</topic>
        <frame_id>rae_imu_frame</frame_id>
        <ignition_frame_id>rae_imu_frame</ignition_frame_id>
      </sensor>
    </gazebo>
    <gazebo>
      <plugin
        filename="ignition-gazebo-imu-system" name="ignition::gazebo::systems::Imu">
      </plugin>
    </gazebo>
  </xacro:if>
  <link name="base_link_back">
    <xacro:body mass="0.00001" d="0.0000010" h="0.000003" w="0.00003">
      <origin xyz="0.0 0.0 0.0" rpy="0.0 0.0 0"/>
    </xacro:body>
  </link>
  <joint name="base_link_back_joint" type="fixed">
    <parent link="base_link"/>
    <child link="base_link_back"/>
    <origin rpy="0 0.0 3.14" xyz="0.0 0.0 0.0" />
  </joint>
  <link name="chassis">
    <xacro:body mass="0.360" d="0.125" h="0.028" w="0.1256">
      <origin xyz="0 0.014 0.0" rpy="0.0 0.0 0.0"/>
    </xacro:body>

    <collision>
      <origin rpy="0.0 0.0 0.0" xyz="0 0.018 0"/>
      <geometry>
        <box size="0.1 0.015 0.1"/>
      </geometry>
    </collision>

    <visual>
      <origin rpy="0.0 3.14 0.0" xyz="0.0 0.0 0.0"/>
      <geometry>
        <mesh filename="package://rae_description/urdf/models/RAE-TOP-ASSY_0417.STL" scale="1.0 1.0 1.0"/>
      </geometry>
      <material name="mat">
        <lighting>1</lighting>
        <color rgba="0.1 0.1 0.1 1.0"/>
        <shader type='pixel'/>
        <emissive>0 0 0 1</emissive>
      </material>
      <transparency>0</transparency>
      <cast_shadows>1</cast_shadows>

    </visual>
  </link>
  <joint name="base_chassis_joint" type="fixed">
    <parent link="base_link"/>
    <child link="chassis"/>
    <origin rpy="1.57 0.0 1.57" xyz="-0.0307 0.0 0.0" />
  </joint>

  <link name="left_wheel">
    <xacro:wheels mass="0.008" h="0.011" r="0.0119">
      <origin xyz="0.0 0.0 -0.0055" rpy="0.0 0.0 0.0"/>
    </xacro:wheels>


    <collision>
      <origin rpy="0.0 0.0 0.0" xyz="0.0 0.0 -0.0055"/>
      <geometry>
        <cylinder length="0.011" radius="0.0119"/>
      </geometry>
    </collision>

    <visual>
      <origin rpy="0.0 0.0 0.0" xyz="0.0 0.0 -0.0055"/>
      <geometry>
        <cylinder length="0.011" radius="0.0119"/>
      </geometry>
    </visual>
  </link>

  <link name="right_wheel">
    <xacro:wheels mass="0.008" h="0.011" r="0.0119">
      <origin xyz="0.0 0.0 -0.0055" rpy="0.0 0.0 0.0"/>
    </xacro:wheels>
    <collision>
      <origin rpy="0.0 0.0 0.0" xyz="0.0 0.0 -0.0055"/>
      <geometry>
        <cylinder length="0.011" radius="0.0119"/>
      </geometry>
    </collision>

    <visual>
      <origin rpy="0.0 0.0 0.0" xyz="0.0 0.0 -0.0055"/>
      <geometry>
        <cylinder length="0.011" radius="0.0119"/>
      </geometry>
    </visual>
  </link>

  <joint name='left_wheel_joint' type='continuous'>
    <origin rpy="1.57 0.0 0.00 " xyz="0.0 0.042 0.0052"/>
    <child link="left_wheel"/>
    <parent link="base_link"/>
    <axis rpy="0 0 0" xyz="0 0 -1"/>
  </joint>

  <joint name='right_wheel_joint' type='continuous'>
    <origin rpy="-1.57 0.0 0.0 " xyz="0.0 -0.042 0.0052"/>
    <child link="right_wheel"/>
    <parent link="base_link"/>
    <axis rpy="0 0 0" xyz="0 0 1"/>
  </joint>

  <link name="left_caster_wheel">
    <xacro:caster_wheels mass="0.008" r="0.005">
      <origin xyz="0.0 0.0 0.0" rpy="0.0 0.0 0.0"/>
    </xacro:caster_wheels>
    <collision>
      <origin rpy="0.0 0.0 0.0" xyz="0.0 0.0 0.0"/>
      <geometry>
        <sphere radius="0.006"/>
      </geometry>
    </collision>

    <visual>
      <origin rpy="0.0 0.0 0.0" xyz="0.0 0.0 0.0"/>
      <geometry>
        <mesh filename="package://rae_description/urdf/models/caster-wheel.stl" scale="1.0 1.0 1.0"/>
      </geometry>
      <material name="mat">
        <lighting>1</lighting>
        <color rgba="1.0 1.0 1.0 1.0"/>
        <shader type='pixel'/>
        <emissive>0 0 0 1</emissive>
      </material>
      <transparency>0</transparency>
      <cast_shadows>1</cast_shadows>

    </visual>
  </link>
  <xacro:if value="$(arg sim_mode)">
    <gazebo reference="left_caster_wheel">
        <mu1>0.0001</mu1>
        <mu2>0.0001</mu2>
    </gazebo>
  </xacro:if>

  <joint name="base_left_caster_wheel" type="fixed">
    <parent link="base_link"/>
    <child link="left_caster_wheel"/>
    <origin rpy="0.0 0.0 0.0" xyz="-0.0735 0.0445 -0.001" />
  </joint>

  <link name="right_caster_wheel">
    <xacro:caster_wheels mass="0.008" r="0.005">
      <origin xyz="0.0 0.0 0.0" rpy="0.0 0.0 0.0"/>
    </xacro:caster_wheels>
    <collision>
      <origin rpy="0.0 0.0 0.0" xyz="0.0 0.0 0.0"/>
      <geometry>
        <sphere radius="0.006"/>
      </geometry>
    </collision>

    <visual>
      <origin rpy="0.0 0.0 0.0" xyz="0.0 0.0 0.0"/>
      <geometry>
        <mesh filename="package://rae_description/urdf/models/caster-wheel.stl" scale="1.0 1.0 1.0"/>
      </geometry>
      <material name="mat">
        <lighting>1</lighting>
        <color rgba="1.0 1.0 1.0 1.0"/>
        <shader type='pixel'/>
        <emissive>0 0 0 1</emissive>
      </material>
      <transparency>0</transparency>
      <cast_shadows>1</cast_shadows>

    </visual>
  </link>
  <xacro:if value="$(arg sim_mode)">
    <gazebo reference="right_caster_wheel">
        <mu1>0.0001</mu1>
        <mu2>0.0001</mu2>
    </gazebo>
  </xacro:if>

  <joint name="base_right_caster_wheel" type="fixed">
    <parent link="base_link"/>
    <child link="right_caster_wheel"/>
    <origin rpy="0.0 0.0 0.0" xyz="-0.0735 -0.0445 -0.001" />
  </joint>


  <link name="rae_rgb_camera_frame">
    <xacro:body mass="0.001" d="0.010" h="0.03" w="0.03">
      <origin xyz="0.0 0.0 0.0" rpy="0.0 0.0 0.0"/>
    </xacro:body>

  </link>

  <link name="rae_rgb_camera_optical_frame">
    <xacro:body mass="0.00001" d="0.0000010" h="0.000003" w="0.00003">
      <origin xyz="0.0 0.0 0.0" rpy="0.0 0.0 0.0"/>
    </xacro:body>

  </link>

  <joint name="rae_rgb_camera_optical_frame_joint" type="fixed">
    <origin xyz="0.0051 0 0" rpy="3.14 3.14 0.0"/>
    <parent link="rae_rgb_camera_frame"/>
    <child link="rae_rgb_camera_optical_frame"/>
  </joint>


  <joint name="rgb_camera_joint" type="fixed">
    <parent link="chassis"/>
    <child link="rae_rgb_camera_frame"/>
    <origin xyz="-0.025 0.0101195 0.0517014" rpy="${-30.0/180*pi} 0 0"/>
  </joint>

  <link name="rae_left_camera_frame">
    <xacro:body mass="0.001" d="0.010" h="0.03" w="0.03">
      <origin xyz="0.0 0.0 0.0" rpy="0.0 0.0 0.0"/>
    </xacro:body>

  </link>

  <joint name="rae_left_camera_joint" type="fixed">
    <parent link="chassis"/>
    <child link="rae_left_camera_frame"/>
    <origin xyz="0.0375 0.0100195 0.0515282" rpy="${-30.0/180*pi} 0 0"/>
  </joint>

  <link name="rae_left_camera_optical_frame">
    <xacro:body mass="0.00001" d="0.0000010" h="0.000003" w="0.00003">
      <origin xyz="0.0 0.0 0.0" rpy="0.0 0.0 0.0"/>
    </xacro:body>

  </link>

  <joint name="rae_left_camera_optical_frame_joint" type="fixed">
    <origin xyz="0.0 0 0" rpy="3.14 3.14 0.0"/>
    <parent link="rae_left_camera_frame"/>
    <child link="rae_left_camera_optical_frame"/>
  </joint>

  <link name="rae_right_camera_frame">
    <xacro:body mass="0.001" d="0.010" h="0.03" w="0.03">
      <origin xyz="0.0 0.0 0.0" rpy="0.0 0.0 0.0"/>
    </xacro:body>

  </link>

  <joint name="rae_right_camera_joint" type="fixed">
    <parent link="chassis"/>
    <child link="rae_right_camera_frame"/>
    <origin xyz="-0.0375 0.0100195 0.0515282" rpy="${-30.0/180*pi} 0 0"/>
  </joint>

  <link name="rae_right_camera_optical_frame">
    <xacro:body mass="0.00001" d="0.0000010" h="0.000003" w="0.00003">
      <origin xyz="0.0 0.0 0.0" rpy="0.0 0.0 0.0"/>
    </xacro:body>

  </link>

  <joint name="rae_right_camera_optical_frame_joint" type="fixed">
    <origin xyz="0.000 0 0" rpy="3.14 3.14 0.0"/>
    <parent link="rae_right_camera_frame"/>
    <child link="rae_right_camera_optical_frame"/>
  </joint>

  <link name="rae_right_back_camera_frame">
    <xacro:body mass="0.001" d="0.010" h="0.03" w="0.03">
      <origin xyz="0.0 0.0 0.0" rpy="0.0 0.0 0.0"/>
    </xacro:body>

  </link>

  <joint name="rae_right_back_camera_joint" type="fixed">
    <parent link="chassis"/>
    <child link="rae_right_back_camera_frame"/>
    <origin xyz="-0.0375 0.0100195 -0.0515282" rpy="${30.0/180*pi} 0 0"/>
  </joint>

  <link name="rae_right_back_camera_optical_frame">
    <xacro:body mass="0.00001" d="0.0000010" h="0.000003" w="0.00003">
      <origin xyz="0.0 0.0 0.0" rpy="0.0 0.0 0.0"/>
    </xacro:body>

  </link>

  <joint name="rae_right_back_camera_optical_frame_joint" type="fixed">
    <origin xyz="0.000 0 0" rpy="3.14 0.0 0.0"/>
    <parent link="rae_right_back_camera_frame"/>
    <child link="rae_right_back_camera_optical_frame"/>
  </joint>

  <link name="rae_left_back_camera_frame">
    <xacro:body mass="0.001" d="0.010" h="0.03" w="0.03">
      <origin xyz="0.0 0.0 0.0" rpy="0.0 0.0 0.0"/>
    </xacro:body>

  </link>

  <joint name="rae_left_back_camera_joint" type="fixed">
    <parent link="chassis"/>
    <child link="rae_left_back_camera_frame"/>
    <origin xyz="0.0375 0.0100195 -0.0515282" rpy="${30.0/180*pi} 0 0"/>
  </joint>

  <link name="rae_left_back_camera_optical_frame">
    <xacro:body mass="0.00001" d="0.0000010" h="0.000003" w="0.00003">
      <origin xyz="0.0 0.0 0.0" rpy="0.0 0.0 0.0"/>
    </xacro:body>

  </link>

  <joint name="rae_left_back_camera_optical_frame_joint" type="fixed">
    <origin xyz="0.000 0 0" rpy="3.14 0.0 0.0"/>
    <parent link="rae_left_back_camera_frame"/>
    <child link="rae_left_back_camera_optical_frame"/>
  </joint>


  <link name="rae_imu_frame"/>
  <joint name="rae_imu_joint" type="fixed">
    <origin xyz="0 0 0" rpy="0 0 0"/>
    <parent link="base_link"/>
    <child link="rae_imu_frame"/>
  </joint>

  <xacro:rae_ros2_control sim_mode="$(arg sim_mode)"/>

  <xacro:if value="$(arg sim_mode)">
    <link name="rae_rgb_camera_sim_frame">
      <xacro:body mass="0.00001" d="0.0000010" h="0.000003" w="0.00003">
        <origin xyz="0.0 0.0 0.0" rpy="0.0 0.0 0.0"/>
      </xacro:body>

    </link>

    <joint name="rae_rgb_camera_sim_frame_joint" type="fixed">
      <origin xyz="0.0 0 0" rpy="${pi/2} ${-pi/2} 0.0"/>
      <parent link="rae_rgb_camera_optical_frame"/>
      <child link="rae_rgb_camera_sim_frame"/>
    </joint>

    <gazebo reference="rae_rgb_camera_sim_frame">
      <sensor type="camera" name="rae_rgb_camera">
        <always_on>true</always_on>
        <update_rate>30.0</update_rate>  
        <topic>/right/image_raw</topic>
        <ignition_frame_id>rae_rgb_camera_optical_frame</ignition_frame_id>
        <camera>
          <horizontal_fov>${105.0/180.0*pi}</horizontal_fov>
          <image>
            <width>320</width>
            <height>240</height>
          </image>  
          <clip>
            <near>0.1</near>
            <far>100</far>
          </clip>
          <noise>
            <type>gaussian</type>
            <mean>0.0</mean>
            <stddev>0.007</stddev>
          </noise>
        </camera>
      </sensor>

      <plugin filename="ignition-gazebo-sensors-system" name="ignition::gazebo::systems::Sensors">
        <engine>ogre2</engine>
      </plugin>
    </gazebo>

    <link name="rae_depth_camera_front_frame">
      <xacro:body mass="0.00001" d="0.00001" h="0.000003" w="0.00001">
        <origin xyz="0.0 0.0 0.0" rpy="0.0 0.0 0.0"/>
      </xacro:body>
    </link>
    
    <joint name="rae_depth_camera_front_frame_joint" type="fixed">
      <origin xyz="${0.0208282} 0.0 0.0100195" rpy="0.0 ${-30.0/180*pi} 0.0"/>
      <parent link="base_link"/>
      <child link="rae_depth_camera_front_frame"/>
    </joint>

    <gazebo reference="rae_depth_camera_front_frame">
      <sensor name="front_depth_camera" type="depth_camera">
        <update_rate>15.0</update_rate>
        <topic>/front/depth/image</topic>
        <ignition_frame_id>rae_depth_camera_front_frame</ignition_frame_id>
        <camera>
          <horizontal_fov>${60.0/180.0*pi}</horizontal_fov>
          <image>
            <width>320</width>
            <height>240</height>
          </image>
          <clip>
            <near>0.2</near>
            <far>6.0</far>
          </clip>
        </camera>
      </sensor>
    </gazebo>

    <link name="rae_depth_camera_rear_frame">
      <xacro:body mass="0.00001" d="0.00001" h="0.00001" w="0.00001">
        <origin xyz="0.0 0.0 0.0" rpy="0.0 0.0 0.0"/>
      </xacro:body>
    </link>

    <joint name="rae_depth_camera_rear_frame_joint" type="fixed">
      <origin xyz="${-0.0822282} 0.0 0.0100195" rpy="0.0 ${-30.0/180*pi} ${pi}"/>
      <parent link="base_link"/>
      <child link="rae_depth_camera_rear_frame"/>
    </joint>

    <gazebo reference="rae_depth_camera_rear_frame">
      <sensor name="rear_depth_camera" type="depth_camera">
        <update_rate>15.0</update_rate>
        <topic>/rear/depth/image</topic>
        <vizualize>true</vizualize>
        <ignition_frame_id>rae_depth_camera_rear_frame</ignition_frame_id>
        <camera>
          <horizontal_fov>${60.0/180.0*pi}</horizontal_fov>
          <image>
            <width>320</width>
            <height>240</height>
          </image>
          <clip>
            <near>0.2</near>
            <far>6.0</far>
          </clip>
        </camera>
      </sensor>
    </gazebo>
  </xacro:if>

</robot>
